Workbook

Sheet 5-Year Comparison
B1: 5-Year Total Cost of Ownership Comparison
B2: All costs in EUR. Compares keeping current car vs. switching to EV.
B4: Cost Category | C4: Year 1 | D4: Year 2 | E4: Year 3 | F4: Year 4 | G4: Year 5 | H4: 5-Year Total
B5: SCENARIO A: Keep Citroën Grand C4 Picasso
B6: Fuel cost | C6: =Assumptions!C17 | D6: =Assumptions!C17 | E6: =Assumptions!C17 | F6: =Assumptions!C17 | G6: =Assumptions!C17 | H6: =SUM(C6:G6)
B7: Road tax | C7: =Assumptions!C18 | D7: =Assumptions!C18 | E7: =Assumptions!C18 | F7: =Assumptions!C18 | G7: =Assumptions!C18 | H7: =SUM(C7:G7)
B8: Insurance | C8: =Assumptions!C19 | D8: =Assumptions!C19 | E8: =Assumptions!C19 | F8: =Assumptions!C19 | G8: =Assumptions!C19 | H8: =SUM(C8:G8)
B9: Maintenance & repairs | C9: =Assumptions!C20 | D9: =Assumptions!C20 | E9: =Assumptions!C20*1.1 | F9: =Assumptions!C20*1.15 | G9: =Assumptions!C20*1.2 | H9: =SUM(C9:G9)
B10: Depreciation (opportunity cost) | C10: 1100 | D10: 1100 | E10: 1100 | F10: 1100 | G10: 1100 | H10: =SUM(C10:G10)
B11: TOTAL ANNUAL COST | C11: =SUM(C6:C10) | D11: =SUM(D6:D10) | E11: =SUM(E6:E10) | F11: =SUM(F6:F10) | G11: =SUM(G6:G10) | H11: =SUM(C11:G11)
B13: SCENARIO B: Large Family EV (Ioniq 5 / Enyaq)
B14: Purchase price | C14: =Assumptions!C26 | D14: 0 | E14: 0 | F14: 0 | G14: 0 | H14: =C14
B15: Less: sale of Picasso | C15: =-Assumptions!C21 | D15: 0 | E15: 0 | F15: 0 | G15: 0 | H15: =-Assumptions!C21
B16: Wallbox installation | C16: =Assumptions!C38 | D16: 0 | E16: 0 | F16: 0 | G16: 0 | H16: =C16
B17: Net upfront cost | C17: =C14+C15+C16 | H17: =H14+H15+H16
B18: Electricity cost | C18: =Assumptions!C32 | D18: =Assumptions!C32 | E18: =Assumptions!C32 | F18: =Assumptions!C32 | G18: =Assumptions!C32 | H18: =SUM(C18:G18)
B19: Road tax | C19: =Assumptions!C33 | D19: =Assumptions!C33 | E19: =Assumptions!C33 | F19: =Assumptions!C34 | G19: =Assumptions!C35 | H19: =SUM(C19:G19)
B20: Insurance | C20: =Assumptions!C36 | D20: =Assumptions!C36 | E20: =Assumptions!C36 | F20: =Assumptions!C36 | G20: =Assumptions!C36 | H20: =SUM(C20:G20)
B21: Maintenance | C21: =Assumptions!C37 | D21: =Assumptions!C37 | E21: =Assumptions!C37 | F21: =Assumptions!C37 | G21: =Assumptions!C37 | H21: =SUM(C21:G21)
B22: Less: resale value at end | C22: 0 | D22: 0 | E22: 0 | F22: 0 | G22: =-Assumptions!C39 | H22: =G22
B23: TOTAL 5-YEAR COST | H23: =H17+H18+H19+H20+H21+H22
B25: SCENARIO C: Small EV + Vacation Rental
B26: Purchase price | C26: =Assumptions!C43 | D26: 0 | E26: 0 | F26: 0 | G26: 0 | H26: =C26
B27: Less: sale of Picasso | C27: =-Assumptions!C21 | D27: 0 | E27: 0 | F27: 0 | G27: 0 | H27: =C27
B28: Wallbox installation | C28: =Assumptions!C52 | D28: 0 | E28: 0 | F28: 0 | G28: 0 | H28: =C28
B29: Net upfront cost | C29: =C26+C27+C28 | H29: =C29
B30: Electricity cost (daily driving) | C30: =Assumptions!C46 | D30: =Assumptions!C46 | E30: =Assumptions!C46 | F30: =Assumptions!C46 | G30: =Assumptions!C46 | H30: =SUM(C30:G30)
B31: Vacation rental cost | C31: =Assumptions!C55 | D31: =Assumptions!C55 | E31: =Assumptions!C55 | F31: =Assumptions!C55 | G31: =Assumptions!C55 | H31: =SUM(C31:G31)
B32: Road tax | C32: =Assumptions!C47 | D32: =Assumptions!C47 | E32: =Assumptions!C47 | F32: =Assumptions!C48 | G32: =Assumptions!C49 | H32: =SUM(C32:G32)
B33: Insurance | C33: =Assumptions!C50 | D33: =Assumptions!C50 | E33: =Assumptions!C50 | F33: =Assumptions!C50 | G33: =Assumptions!C50 | H33: =SUM(C33:G33)
B34: Maintenance | C34: =Assumptions!C51 | D34: =Assumptions!C51 | E34: =Assumptions!C51 | F34: =Assumptions!C51 | G34: =Assumptions!C51 | H34: =SUM(C34:G34)
B35: Less: resale value at end | C35: 0 | D35: 0 | E35: 0 | F35: 0 | G35: =-Assumptions!C56 | H35: =G35
B36: TOTAL 5-YEAR COST | H36: =H29+H30+H31+H32+H33+H34+H35
B38: COST SUMMARY PER SCENARIO
B39: Scenario | C39: Year 1 Total | D39: Avg Annual (Yr 1-3) | E39: Avg Annual (Yr 1-5) | F39: 5-Year Grand Total
B40: A: Keep Picasso | C40: =C11 | D40: =SUM(C11:E11)/3 | E40: =H11/5 | F40: =H11
B41: B: Large Family EV | C41: =C17+C18+C19+C20+C21 | D41: =(C17+C18+C19+C20+C21 + D18+D19+D20+D21 + E18+E19+E20+E21)/3 | E41: =H23/5 | F41: =H23
B42: C: Small EV + Rental | C42: =C29+C30+C31+C32+C33+C34 | D42: =(C29+C30+C31+C32+C33+C34 + D30+D31+D32+D33+D34 + E30+E31+E32+E33+E34)/3 | E42: =H36/5 | F42: =H36
B44: SAVINGS vs. KEEPING PICASSO
B45: Scenario | C45: Year 1 Saving | D45: Avg Annual Saving (3yr) | E45: Avg Annual Saving (5yr) | F45: 5-Year Total Saving
...

Sheet EV Shortlist
B1: Second-Hand EV Shortlist — Replacing the Grand C4 Picasso
B2: All models: under 100,000 km, 2021-2024, available on Dutch market. Prices in EUR.
B4: YOUR CURRENT CAR FOR REFERENCE
C5: Boot | D5: Rear Legroom | E5: Rear Headroom | F5: Pano Roof | G5: Rev Camera | H5: Park Assist | I5: Seats | J5: Notes
B6: Citroën Grand C4 Picasso | C6: 645–704 L (2,181 L flat) | D6: Excellent | E6: Excellent | F6: Yes | G6: Yes | H6: Yes | I6: 5 (or 7) | J6: The benchmark — spacious, airy, family-optimised
B8: RECOMMENDED — TIER 1 (Best match for your family)
B9: Model | C9: NL Price Range | D9: Boot | E9: Rear Legroom | F9: Pano Roof | G9: Rev Camera | H9: Park Assist | I9: Battery/Range | J9: DC Charge | K9: Why / Watch Out
B10: Skoda Enyaq iV ★ | C10: €26,000-32,000 | D10: 585 L (~10% smaller) | E10: Very good | F10: Higher trims | G10: Yes | H10: Higher trims | I10: 62-82 kWh 340-510 km | J10: 135 kW | K10: Closest to Picasso: biggest boot, flat rear floor, practical "Simply Clever" touches. Watch for: infotainment glitches on some units.
B11: Hyundai Ioniq 5 ★ | C11: €26,000-30,000 | D11: 527 L (~20% smaller) | E11: Excellent | F11: Connect+ trims | G11: Yes (all) | H11: Yes (all) | I11: 58-73 kWh 350-480 km | J11: 220 kW | K11: Modern, spacious, ultra-fast 800V charging. Panoramic roof on Connect/Lounge. Watch for: 12V battery issues, check charging history.
B12: Kia EV6 | C12: €27,000-33,000 | D12: 490 L (~25% smaller) | E12: Best in class | F12: Higher trims | G12: Yes | H12: Yes | I12: 58-77 kWh 370-510 km | J12: 220 kW | K12: "Limo-like" rear legroom — best for tall adults in back. 800V fast charging. Slightly above ideal budget.
B14: TIER 2 — Good alternatives
B15: Model | C15: NL Price Range | D15: Boot | E15: Rear Legroom | F15: Pano Roof | G15: Rev Camera | H15: Park Assist | I15: Battery/Range | J15: DC Charge | K15: Why / Watch Out
B16: VW ID.4 | C16: €17,000-25,000 | D16: 543 L (~16% smaller) | E16: Good | F16: Option | G16: Yes | H16: Higher trims | I16: 52-77 kWh 320-480 km | J16: 135 kW | K16: Solid, reliable, wide dealer network. Less exciting than Ioniq 5 but dependable. Slightly less rear space.
B17: Tesla Model Y | C17: €28,000-35,000 | D17: 854 L (~30% bigger) | E17: Very good | F17: Glass roof std | G17: Yes | H17: Yes | I17: 60-75 kWh 390-500 km | J17: 250 kW | K17: Largest boot of all candidates. Supercharger network excellent. Stretches budget to €30k+ for decent examples.
B19: AVOID — Not suitable for your family needs
B20: Model | C20: NL Price Range | D20: Boot | E20: Rear Legroom | F20: Pano Roof | G20: Rev Camera | H20: Park Assist | I20: Battery/Range | J20: DC Charge | K20: Why to avoid
B21: Tesla Model 3 | C21: €15,000-26,000 | D21: 561 L (~13% smaller) | E21: Poor | F21: Glass roof | G21: Yes | H21: Yes | I21: 60-75 kWh 400-500 km | J21: 250 kW | K21: Rear seat too low — poor thigh support, tight headroom. Not designed as family car. Sedan, not SUV/MPV.
B22: MG4 | C22: €15,000-20,000 | D22: 363 L (~44% smaller) | E22: Tight | F22: No | G22: Varies | H22: Varies | I22: 51-64 kWh 300-400 km | J22: 100 kW | K22: No rear interior light (car seat nightmare), no rear air vents, small boot. Great budget EV but wrong car for families.
B23: Peugeot e-2008 | C23: €16,000-25,000 | D23: 434 L (~33% smaller) | E23: Tight | F23: No | G23: Varies | H23: Varies | I23: 50 kWh ~300 km | J23: 100 kW | K23: Too compact. Cramped rear for 2 adults + kids. Better as a city runabout (Scenario C) than family replacement.
B24: Hyundai Ioniq 6 | C24: €29,000-45,000 | D24: 401 L (~38% smaller) | E24: Poor | F24: No | G24: Yes | H24: Yes | I24: 53-77 kWh 370-510 km | J24: 220 kW | K24: Sedan with sloping roof — terrible rear headroom. Pricey. Wrong body style entirely.
B26: PRE-PURCHASE CHECKLIST FOR ANY USED EV
B27: 1. Get independent battery health report (state of health %) — costs ~€100-200 at most EV specialists.
B28: 2. Ask for full service history — look for charging port repairs, 12V battery replacements, software update log.
B29: 3. Check remaining manufacturer battery warranty (8-10 years depending on brand).
B30: 4. Test DC fast charging during viewing — confirm it reaches advertised speed without throttling.
B31: 5. Verify trim level has reversing camera and parking sensors (not all base trims include these).
B32: 6. Check tyre condition — EV tyres wear 20-30% faster due to vehicle weight. Budget for replacement.
B33: 7. Use RDW.nl to verify Dutch registration, import history, and APK (MOT) status.
B34: 8. ASK: Does this car have a HEAT PUMP? Critical for winter range. Not standard on all trims. Adds 15-25% winter range vs resistive heater.
B35: 9. ASK: Battery cooling system — is it liquid-cooled? (All 3 recommended EVs are, but verify coolant has been maintained.)
B36: 10. ASK: Has battery coolant ever been changed? Check coolant level and condition during viewing.
B37: 11. ASK: Any battery-related warning lights or error codes in history? Ask dealer to show diagnostic scan.
... B53: 19. CHECK: Inspect undercarriage for corrosion, scrapes, and battery tray damage. Dutch salt roads accelerate rust. Use phone torch.

Sheet Features & Trims
B1: Feature Comparison by Model & Trim
B2: COLOR KEY: ✅ Green = Included as standard | ⚠ Orange = Available as option / higher trim | ❌ Red = Not available
B4: YOUR WISHLIST vs. REALITY
B5: Your Feature (priority order) | C5: Prio | D5: Enyaq iV (Edition / L&K) | E5: Ioniq 5 (Lounge / Ultimate) | F5: EV6 (Wind / GT-Line) | G5: Notes
B6: Predictive ACC (nav-based) | C6: 1 | D6: ⚠ pACC (Assist pkg) | E6: ✅ NSCC (all trims) | F6: ✅ NSCC-C (all trims) | G6: Enyaq needs an option package for this. Ioniq 5 has it on every trim.
B7: Blind spot detection | C7: 2 | D7: ⚠ Side Assist pkg | E7: ✅ Standard (all) | F7: ✅ Standard (all) | G7: Nice-to-have, not a must. Both Korean cars have it standard. Enyaq doesn't — less of an issue now.
B8: Traffic sign recognition | C8: 3 | D8: ✅ Standard (all) | E8: ✅ Standard (all) | F8: ✅ Standard (all) | G8: EV6 GT-Line is the only one where it's guaranteed without checking options.
B9: Panoramic sunroof | C9: 4 | D9: ⚠ Option (~€1,000) | E9: ⚠ Lounge+ | F9: ✅ Std on GT-Line | G9: Enyaq actually wins here with tri-zone. All are fine.
B10: Reversing camera | C10: 5 | D10: ✅ Standard (all) | E10: ✅ Std on Lounge+ | F10: ✅ Std on Wind+ | G10: EV6 GT-Line includes remote smart parking as standard. Ioniq 5 Lounge includes RSPA. Enyaq needs Parking Plus / Maxx package (common on Business Edition).
B11: Park assist (auto steering) | C11: 6 | D11: ⚠ Parking Plus pkg | E11: ✅ SPA (Lounge+) | F11: ✅ SPA (GT-Line std) | G11: Just reversing camera needed (not 360°). Ioniq 5 Lounge has it, EV6 Wind+, Enyaq needs pkg.
B12: Electric tailgate | C12: 7 | D12: ❌ Not available | E12: ✅ Standard (all) | F12: ✅ Standard (all) | G12: All need higher trims. Ioniq 5 Ultimate has real leather; others are synthetic.
B13: Air conditioning | C13: 8 | D13: ✅ Tri-zone (all) | E13: ✅ Dual-zone (all) | F13: ✅ Dual-zone (all) | G13: MPV-only feature. None of these have it. Aftermarket tablet holders exist (€30-50).
B14: Leather / premium seats | C14: 9 | D14: ⚠ Suite / L&K trim | E14: ⚠ Ultimate / N Line S | F14: ⚠ GT-Line (suede) | G14: Only the Enyaq Edition has built-in manual blinds. Others: buy magnetic shades (€25).
B15: Fold-out rear tables | C15: 10 | D15: ❌ Not available | E15: ❌ Not available | F15: ❌ Not available | G15: Privacy glass standard on Ioniq 5 and EV6. Enyaq needs a package again.
B16: Rear window blinds | C16: 11 | D16: ✅ Edition trim only | E16: ❌ Privacy glass only | F16: ❌ Privacy glass only | G16: EVs hold position automatically on hills. The motor provides instant holding torque.
B17: Tinted rear windows | C17: 12 | D17: ⚠ Convenience pkg | E17: ✅ Standard (all) | F17: ✅ Standard (all) | G17: Enyaq and EV6 have it across the board. Ioniq 5 base trim doesn't.
B18: Hill start assist | C18: 13 | D18: ✅ Not needed | E18: ✅ Not needed | F18: ✅ Not needed
B19: Wireless phone charging | C19: 14 | D19: ✅ Standard (all) | E19: ⚠ Connect+ and above | F19: ✅ Standard (all)
B20: Cooled seats | C20: 15 | D20: ❌ Not available | E20: ❌ Not available | F20: ⚠ GT-Line S only
B21: Wireless CarPlay/Android Auto | C21: 16 | D21: ✅ Standard (all) | E21: ⚠ Connect+ and above | F21: ✅ Standard (all)
B22: FEATURE SCORECARD
D23: Enyaq iV | E23: Ioniq 5 | F23: EV6
B24: Features standard (no extra cost) | D24: 7 / 16 | E24: 9 / 16 | F24: 12 / 16 | G24: EV6 GT-Line includes the most as standard
B25: Features available (std + optional) | D25: 13 / 16 | E25: 13 / 16 | F25: 14 / 16 | G25: All miss fold-out tables; Enyaq misses electric tailgate
B26: Not available at all | D26: 3 / 16 | E26: 3 / 16 | F26: 2 / 16 | G26: Tables and tailgate (Enyaq) or tables and blinds (Ioniq/EV6)
B29: RECOMMENDED TRIM LEVEL & PRICE IMPACT
B30: Model | D30: Trim to target | E30: Second-hand price | F30: Gets you | G30: What you miss
B31: Hyundai Ioniq 5 | D31: Lounge or Ultimate | E31: €24,000 - 29,000 | F31: ACC, power tailgate, 360° cam, pano roof, leather (Ultimate), privacy glass, wireless charge | G31: No tables, no built-in blinds (buy magnetic €25)
B32: Kia EV6 | D32: GT-Line | E32: €27,000 - 32,000 | F32: ACC, power tailgate, pano roof std, 360° cam, parking assist, wireless charge, suede seats | G32: No tables, no built-in blinds (buy magnetic €25). Pushes budget.
B33: Skoda Enyaq iV | D33: Business Ed or L&K | E33: €24,000 - 30,000 | F33: Tri-zone AC, wireless charge, rear blinds (Edition). Must add Assistance + Parking pkgs. | G33: No electric tailgate. ACC costs extra. But pano roof and park assist available as options — look for well-spec Business Edition models.
B35: VERDICT
B36: The Ioniq 5 Lounge/Ultimate is the best match for your feature wishlist.
B37: It ticks the most boxes as standard, including blind spot detection, traffic sign recognition, and ACC on every trim.
B38: The Enyaq — previously our top pick for space — has more options than we thought: panoramic roof and park assist are both available (common on Business Edition). No electric tailgate is still a miss.
B39: The EV6 GT-Line ticks even more boxes but pushes your budget to ~€30k.
B41: NOTES ON NEW FEATURES
B42: Traffic sign recognition (ISLA): standard on ALL three cars, ALL trims. Shows current speed limit in instrument cluster.
B43: Blind spot detection: standard on Ioniq 5 & EV6 (all trims). On Enyaq, requires Side Assist package — check it's fitted.
B44: Predictive ACC: All 3 cars have nav-based ACC that slows for curves, roundabouts, speed limits. Ioniq 5 = NSCC (std all trims). EV6 = NSCC-C (std all trims). Enyaq = pACC (ACC is predictive by design — if it has ACC, it has pACC. ACC itself needs Assisted Drive pkg).
B45: Park assist: Ioniq 5 & EV6 = "Smart Parking Assist" (SPA) — car measures space, steers for parallel/perpendicular. Enyaq = part of Parking Plus pkg (Park Assist + 360° camera + Trained Parking). NOT standard on any Enyaq trim.
...

Sheet Assumptions
B1: Family Car Project — Key Assumptions
B2: All values in EUR unless stated. Blue = editable input.
B4: GENERAL ASSUMPTIONS
B5: Parameter | C5: Value | D5: Unit | E5: Notes
B6: Ownership period | C6: 5 | D6: years | E6: How long you plan to keep the new car
B7: Annual kilometres driven | C7: 20000 | D7: km | E7: Total annual driving
B8: Vacation km per year | C8: 4000 | D8: km | E8: Km driven during 3-4 weeks vacation
B9: Daily driving km per year | C9: 16000 | D9: km | E9: Total minus vacation km
B10: Vacation rental weeks per year | C10: 3 | D10: weeks (3 weeks SUV rental, e.g. Volvo XC60) | E10: Scenario C only
B11: Location | C11: Spaarndam, Noord-Holland | E11: Affects road tax (opcenten)
B13: CURRENT CAR: CITROËN GRAND C4 PICASSO 1.2 PURETECH (2017)
B14: Parameter | C14: Value | D14: Unit | E14: Notes
B15: Fuel consumption (real-world) | C15: 7.5 | D15: L/100km | E15: You use ~50L every 2 weeks = ~1,300L/yr = ~17,300 km at this rate
B16: Petrol price (Euro 95) | C16: 2 | D16: €/litre | E16: Typical NL price (varies €1.85-2.53)
B17: Annual fuel cost | C17: =C7*(C15/100)*C16 | D17: €/year | E17: NL price used; vacation fuel abroad is cheaper (see sensitivity)
B18: Road tax (motorrijtuigenbelasting) | C18: 796 | D18: €/year | E18: Est. for ~1,392kg petrol, Noord-Holland
B19: Insurance (WA+ / allrisk) | C19: 852 | D19: €/year | E19: €71/month actual
B20: Annual maintenance & service | C20: 450 | D20: €/year | E20: Service + wear items
B21: Estimated resale value now | C21: 6909 | D21: € | E21: €6,500 realistic private sale at 174,000 km (belt overdue, high mileage)
B22: Estimated resale in 5 years | C22: 1000 | D22: € | E22: 2017 PureTech at ~274k km in 5 years — near scrap value
B24: SCENARIO B: LARGE FAMILY EV (e.g. Hyundai Ioniq 5 / Skoda Enyaq)
B25: Parameter | C25: Value | D25: Unit | E25: Notes
B26: Purchase price (second-hand) | C26: 27000 | D26: € | E26: 2021-2023 model, good condition
B27: Electricity consumption | C27: 18 | D27: kWh/100km | E27: Real-world average for mid-size EV
B28: Home charging cost | C28: 0.22 | D28: €/kWh | E28: Avg NL home tariff incl. network costs
B29: Public charging cost (avg) | C29: 0.45 | D29: €/kWh | E29: Mix of AC public + occasional DC
B30: Home vs public charging split | C30: 0.75 | E30: 75% home, 25% public
B31: Blended electricity cost per kWh | C31: =C30*C28+(1-C30)*C29 | D31: €/kWh | E31: Weighted average of home + public
B32: Annual electricity cost | C32: =C7*(C27/100)*C31 | D32: €/year | E32: km x consumption x blended price
B33: Road tax (2026-2028: 30% discount) | C33: 1008 | D33: €/year | E33: Est. 70% of ~€515 base for EV weight
B34: Road tax (2029: 25% discount) | C34: 1080 | D34: €/year | E34: 75% of base
B35: Road tax (2030+: full rate) | C35: 1440 | D35: €/year | E35: Full rate from 2030
B36: Insurance | C36: 1050 | D36: €/year | E36: ~20% more than Picasso. Higher car value (€23k vs €8.5k) + EV surcharge (~16-20%). Based on NL research.
B37: Annual maintenance | C37: 500 | D37: €/year | E37: Service, tyres, brakes (regen helps)
B38: Home wallbox installation | C38: 1200 | D38: € | E38: One-time: charger hardware + install
B39: Estimated resale in 5 years | C39: 13500 | D39: € | E39: Conservative: EVs hold value well
B41: SCENARIO C: SMALL RUNAROUND EV + VACATION RENTAL
B42: Parameter | C42: Value | D42: Unit | E42: Notes
B43: Purchase price (second-hand) | C43: 13000 | D43: € | E43: e.g. Renault Zoe / Nissan Leaf 2020-2022
B44: Electricity consumption | C44: 15 | D44: kWh/100km | E44: Smaller, lighter EV = more efficient
...

Sheet Notes & Research
B1: Research Notes & Key Findings
B3: YOUR CURRENT CAR
B4: The Citroën Grand C4 Picasso 1.2 PureTech was available from the 2016 facelift onwards. Your 2017 registration is consistent.
B5: Real-world fuel consumption is ~7.5 L/100km (47% above the official 5.1 L/100km figure).
B6: At current NL petrol prices of €2.53/L and 20,000 km/year, you spend ~€3,795/year on fuel alone.
B7: Estimated private sale value: €5,500-7,500 at 174,000 km (timing belt overdue, high mileage).
B9: EV INSURANCE IN THE NETHERLANDS
B10: EV insurance premiums are typically 15-20% higher than equivalent ICE vehicles.
B11: Main reason: battery repair/replacement is expensive (30-50% of vehicle value).
B12: However, overall TCO savings from fuel and maintenance often more than offset this.
B13: Tip: Use Dutch comparison sites (Independer, Pricewise) for accurate quotes for specific models.
B15: ROAD TAX (MOTORRIJTUIGENBELASTING) CHANGES
... B36: NL registration H416GS — Dutch registrations don't directly encode the year. The 2017 model year is plausible for this engine.

Sheet Fuel Price Sensitivity
B1: Fuel Price Sensitivity Analysis
B2: NL petrol won't drop below €2.00/L — this shows the upside risk of keeping the Picasso.
B4: ANNUAL FUEL COST AT DIFFERENT PETROL PRICES
B5: Petrol Price | C5: Annual Fuel Cost | D5: Monthly Fuel Cost | E5: EV Electricity Cost | F5: Annual Saving with EV
B6: 2 | C6: =Assumptions!C7*(Assumptions!C15/100)*B6 | D6: =C6/12 | E6: =Assumptions!C32 | F6: =C6-E6 | G6: ← Your typical price now
B7: 2.1 | C7: =Assumptions!C7*(Assumptions!C15/100)*B7 | D7: =C7/12 | E7: =Assumptions!C32 | F7: =C7-E7
B8: 2.2 | C8: =Assumptions!C7*(Assumptions!C15/100)*B8 | D8: =C8/12 | E8: =Assumptions!C32 | F8: =C8-E8
B9: 2.3 | C9: =Assumptions!C7*(Assumptions!C15/100)*B9 | D9: =C9/12 | E9: =Assumptions!C32 | F9: =C9-E9
B10: 2.4 | C10: =Assumptions!C7*(Assumptions!C15/100)*B10 | D10: =C10/12 | E10: =Assumptions!C32 | F10: =C10-E10
B11: 2.53 | C11: =Assumptions!C7*(Assumptions!C15/100)*B11 | D11: =C11/12 | E11: =Assumptions!C32 | F11: =C11-E11
B12: 2.7 | C12: =Assumptions!C7*(Assumptions!C15/100)*B12 | D12: =C12/12 | E12: =Assumptions!C32 | F12: =C12-E12
B13: 2.9 | C13: =Assumptions!C7*(Assumptions!C15/100)*B13 | D13: =C13/12 | E13: =Assumptions!C32 | F13: =C13-E13
B16: 5-YEAR TOTAL COST AT EACH FUEL PRICE
B17: EV scenarios are immune to fuel price swings — only the Picasso line moves.
B18: Petrol Price | C18: A: Keep Picasso | D18: B: Large EV | E18: C: Small EV+Rental | F18: B saves vs A | G18: C saves vs A
B19: 2 | C19: =5*Assumptions!C7*(Assumptions!C15/100)*B19+Assumptions!C18*5+Assumptions!C19*5+Assumptions!C20*(1+1+1.1+1.15+1.2)+(Assumptions!C21-Assumptions!C22) | D19: ='5-Year Comparison'!H23 | E19: ='5-Year Comparison'!H36 | F19: =C19-D19 | G19: =C19-E19
B20: 2.1 | C20: =5*Assumptions!C7*(Assumptions!C15/100)*B20+Assumptions!C18*5+Assumptions!C19*5+Assumptions!C20*(1+1+1.1+1.15+1.2)+(Assumptions!C21-Assumptions!C22) | D20: ='5-Year Comparison'!H23 | E20: ='5-Year Comparison'!H36 | F20: =C20-D20 | G20: =C20-E20
B21: 2.2 | C21: =5*Assumptions!C7*(Assumptions!C15/100)*B21+Assumptions!C18*5+Assumptions!C19*5+Assumptions!C20*(1+1+1.1+1.15+1.2)+(Assumptions!C21-Assumptions!C22) | D21: ='5-Year Comparison'!H23 | E21: ='5-Year Comparison'!H36 | F21: =C21-D21 | G21: =C21-E21
B22: 2.3 | C22: =5*Assumptions!C7*(Assumptions!C15/100)*B22+Assumptions!C18*5+Assumptions!C19*5+Assumptions!C20*(1+1+1.1+1.15+1.2)+(Assumptions!C21-Assumptions!C22) | D22: ='5-Year Comparison'!H23 | E22: ='5-Year Comparison'!H36 | F22: =C22-D22 | G22: =C22-E22
B23: 2.4 | C23: =5*Assumptions!C7*(Assumptions!C15/100)*B23+Assumptions!C18*5+Assumptions!C19*5+Assumptions!C20*(1+1+1.1+1.15+1.2)+(Assumptions!C21-Assumptions!C22) | D23: ='5-Year Comparison'!H23 | E23: ='5-Year Comparison'!H36 | F23: =C23-D23 | G23: =C23-E23
B24: 2.53 | C24: =5*Assumptions!C7*(Assumptions!C15/100)*B24+Assumptions!C18*5+Assumptions!C19*5+Assumptions!C20*(1+1+1.1+1.15+1.2)+(Assumptions!C21-Assumptions!C22) | D24: ='5-Year Comparison'!H23 | E24: ='5-Year Comparison'!H36 | F24: =C24-D24 | G24: =C24-E24
B25: 2.7 | C25: =5*Assumptions!C7*(Assumptions!C15/100)*B25+Assumptions!C18*5+Assumptions!C19*5+Assumptions!C20*(1+1+1.1+1.15+1.2)+(Assumptions!C21-Assumptions!C22) | D25: ='5-Year Comparison'!H23 | E25: ='5-Year Comparison'!H36 | F25: =C25-D25 | G25: =C25-E25
B26: 2.9 | C26: =5*Assumptions!C7*(Assumptions!C15/100)*B26+Assumptions!C18*5+Assumptions!C19*5+Assumptions!C20*(1+1+1.1+1.15+1.2)+(Assumptions!C21-Assumptions!C22) | D26: ='5-Year Comparison'!H23 | E26: ='5-Year Comparison'!H36 | F26: =C26-D26 | G26: =C26-E26
B28: KEY INSIGHT
B29: Every €0.10/L increase adds ~€750/year to Picasso costs. EV costs don't change.
B30: At your current €2.00/L, the large EV saves ~€18,000 over 5 years.
B31: If fuel rises to €2.53/L again, savings jump to ~€22,000+.
B32: Fuel prices can only go up from €2.00 — every increase makes the EV case stronger.
B34: YOUR FUEL USAGE CROSS-CHECK
B35: Tank size: | C35: 50 | D35: litres
B36: Fill-ups per year: | C36: 26 | D36: (every 2 weeks)
B37: Annual litres used: | C37: =C35*C36 | D37: litres
B38: Implied annual km (NL driving): | C38: =C37/(Assumptions!C15/100) | D38: km
B39: Your stated total annual km: | C39: =Assumptions!C7 | D39: km
B40: Vacation driving (cheaper foreign fuel): | C40: =C39-C38 | D40: km — fuelled in UK/Belgium at lower prices

Sheet Selling the Picasso
B1: Selling Your Citroën Grand C4 Picasso
B2: 2017 | 1.2 PureTech | ~174,000 km | Registration: H416GS
B4: WHAT YOU CAN EXPECT TO GET
B5: Selling method | C5: Expected price | D5: Timeframe | E5: Notes
B6: Private sale (Marktplaats) | C6: €5,500 – 7,500 | D6: 2-6 weeks | E6: Best price but most effort. High mileage + overdue belt will attract negotiation
B7: Private sale (AutoScout24) | C7: €5,500 – 7,500 | D7: 2-6 weeks | E7: Same as Marktplaats; list on both for wider reach
B8: Online buying service | C8: €4,500 – 6,000 | D8: 24-48 hours | E8: Ikwilvanmijnautoaf.nl, Wijkopenautos.nl — fast, fair, lower for high-km cars
B9: Dealer trade-in | C9: €3,500 – 5,000 | D9: Same day | E9: Easiest but worst deal. Only if buying from that dealer
B11: THE TIMING BELT QUESTION
B12: Option | C12: Cost / Impact | D12: Net Effect | E12: Verdict
B13: Replace belt, then sell | C13: Costs you €700 | D13: Adds ~€200-400 to sale price | E13: You lose €300-500. Don't do this.
B14: Sell with belt due/overdue | C14: Costs you €0 | D14: Buyers knock €300-500 off | E14: Better outcome. Be upfront about it.
B16: WHAT AFFECTS YOUR SALE PRICE
B17: Factor | C17: Impact | D17: Your situation | E17: Action needed
B18: Timing belt status | C18: CRITICAL | D18: Severely overdue at 174k km — buyers will discount heavily | E18: Be upfront. Price already reflects it.
B19: APK (MOT) status | C19: High | D19: Check if current — expiry date? | E19: Get APK done if expiring (costs €30-60)
B20: Service history | C20: High | D20: Is it complete? | E20: Gather all records, invoices, stamps
B21: Mileage | C21: Moderate | D21: 174,000 km — high for a 2017 | E21: Expect buyers to use this as negotiation leverage
B22: Cosmetic condition | C22: Moderate | D22: Assumed good | E22: Clean inside and out before photos
B23: Season | C23: Moderate | D23: March 2026 — perfect timing! | E23: Spring is best for family cars
B24: Number of owners | C24: Low | D24: Check via RDW.nl | E24: Fewer owners = better
B26: SELLING CHECKLIST
B27: 1. Check APK expiry date (RDW.nl) — renew if expiring within 2 months (€30-60)
B28: 2. Gather full service history — invoices, stamp book, any recall paperwork
B29: 3. Give it a proper clean — inside and out, including boot. First impressions matter.
B30: 4. Take good photos — daylight, clean background, show interior, boot, dashboard, engine bay
B31: 5. List on both Marktplaats AND AutoScout24 for maximum reach
B32: 6. Set asking price at €9,000-9,500 to leave room for negotiation down to €8,000-8,500
B33: 7. Be honest about the timing belt — buyers who know PureTech will respect transparency
B34: 8. Meanwhile, get a quick online quote from Ikwilvanmijnautoaf.nl as your fallback price
B35: 9. When selling privately: both parties go to PostNL together to transfer registration
B36: 10. Don't spend €700 on the timing belt. Sell as-is.
